Workbook
Name ChungChi: [1]ViTriLamViec!#REF!
Name ChungChi: [1]ViTriLamViec!#REF!
Name ChuyenNghanh: [1]DM_NganhDT!#REF!
Name ChuyenNghanh: [1]DM_NganhDT!#REF!
Name CoSoDaoTao: #REF!
Name CoSoDaoTao: #REF!
Name CoSoDaoTao_: #REF!
Name DanhMucPhong: #REF!
Name DanhMucPhong: #REF!
Name DanToc: [1]DanToc!#REF!
Name DanToc: [1]DanToc!#REF!

Sheet Ke hoach giảng dạy CNTT
A1: TRƯỜNG ĐẠI HỌC VĂN LANG
A2: KHOA CÔNG NGHỆ THÔNG TIN
A4: KẾ HOẠCH ĐÀO TẠO NGÀNH CÔNG NGHỆ THÔNG TIN - KHÓA 30 | N4: =SUM(N9:N100) -> 126
E6: 2 | F6: 4 | G6: 5 | H6: 6 | I6: 7 | J6: 8 | K6: 9 | L6: 10 | M6: 11
A7: TT | B7: Phân bổ học kỳ | C7: Năm Thứ | D7: Mã học phần | E7: Tên học phần (Tiếng Việt) | F7: Số tín chỉ | G7: Số tiết/giờ | K7: Bắt buộc/Tự chọn | L7: ĐK tiên quyết | M7: ĐK học trước | N7: Số TC/ HK | O7: Ghi chú
G8: LT | H8: TH | I8: ĐA | J8: TT
A9: HK241 1 | B9: 1 | C9: 1 | D9: 71ENG110013 | E9: =VLOOKUP($D9,'[2]Khung_CTĐT_CNTT_K30 (2024)'!$B$10:$L$96,'Ke hoach giảng dạy CNTT'!E$6,0) -> Anh văn 1 (AV1) | F9: =VLOOKUP($D9,'[2]Khung_CTĐT_CNTT_K30 (2024)'!$B$10:$L$96,'Ke hoach giảng dạy CNTT'!F$6,0) -> 3 | G9: =VLOOKUP($D9,'[2]Khung_CTĐT_CNTT_K30 (2024)'!$B$10:$L$96,'Ke hoach giảng dạy CNTT'!G$6,0) -> 30 | H9: =VLOOKUP($D9,'[2]Khung_CTĐT_CNTT_K30 (2024)'!$B$10:$L$96,'Ke hoach giảng dạy CNTT'!H$6,0) -> 30 | I9: =VLOOKUP($D9,'[2]Khung_CTĐT_CNTT_K30 (2024)'!$B$10:$L$96,'Ke hoach giảng dạy CNTT'!I$6,0) -> 0 | J9: =VLOOKUP($D9,'[2]Khung_CTĐT_CNTT_K30 (2024)'!$B$10:$L$96,'Ke hoach giảng dạy CNTT'!J$6,0) -> 0 | K9: =VLOOKUP($D9,'[2]Khung_CTĐT_CNTT_K30 (2024)'!$B$10:$L$96,'Ke hoach giảng dạy CNTT'!K$6,0) -> BB | L9: =VLOOKUP($D9,'[2]Khung_CTĐT_CNTT_K30 (2024)'!$B$10:$L$96,'Ke hoach giảng dạy CNTT'!L$6,0) -> [71ENG010012]Anh văn dự bị (AV0) | M9: =VLOOKUP($D9,'[2]Khung_CTĐT_CNTT_K30 (2024)'!$B$10:$L$96,'Ke hoach giảng dạy CNTT'!M$6,0) -> Không | N9: =SUM(F9:F12) -> 12 | P9: 12 | Q9: 1
B10: 1 | C10: 1 | D10: 71ITBS10103 | E10: =VLOOKUP($D10,'[2]Khung_CTĐT_CNTT_K30 (2024)'!$B$10:$L$96,'Ke hoach giảng dạy CNTT'!E$6,0) -> Nhập môn Công nghệ thông tin | F10: =VLOOKUP($D10,'[2]Khung_CTĐT_CNTT_K30 (2024)'!$B$10:$L$96,'Ke hoach giảng dạy CNTT'!F$6,0) -> 3 | G10: =VLOOKUP($D10,'[2]Khung_CTĐT_CNTT_K30 (2024)'!$B$10:$L$96,'Ke hoach giảng dạy CNTT'!G$6,0) -> 30 | H10: =VLOOKUP($D10,'[2]Khung_CTĐT_CNTT_K30 (2024)'!$B$10:$L$96,'Ke hoach giảng dạy CNTT'!H$6,0) -> 30 | I10: =VLOOKUP($D10,'[2]Khung_CTĐT_CNTT_K30 (2024)'!$B$10:$L$96,'Ke hoach giảng dạy CNTT'!I$6,0) -> 0 | J10: =VLOOKUP($D10,'[2]Khung_CTĐT_CNTT_K30 (2024)'!$B$10:$L$96,'Ke hoach giảng dạy CNTT'!J$6,0) -> 0 | K10: =VLOOKUP($D10,'[2]Khung_CTĐT_CNTT_K30 (2024)'!$B$10:$L$96,'Ke hoach giảng dạy CNTT'!K$6,0) -> BB | L10: =VLOOKUP($D10,'[2]Khung_CTĐT_CNTT_K30 (2024)'!$B$10:$L$96,'Ke hoach giảng dạy CNTT'!L$6,0) -> Không | M10: =VLOOKUP($D10,'[2]Khung_CTĐT_CNTT_K30 (2024)'!$B$10:$L$96,'Ke hoach giảng dạy CNTT'!M$6,0) -> Không | Q10: =Q9 -> 1 | R10: =IFERROR(VLOOKUP(D10,$D$9:D9,1,0),"")
B11: 1 | C11: 1 | D11: 71ITBS10203 | E11: =VLOOKUP($D11,'[2]Khung_CTĐT_CNTT_K30 (2024)'!$B$10:$L$96,'Ke hoach giảng dạy CNTT'!E$6,0) -> Cơ sở lập trình | F11: =VLOOKUP($D11,'[2]Khung_CTĐT_CNTT_K30 (2024)'!$B$10:$L$96,'Ke hoach giảng dạy CNTT'!F$6,0) -> 3 | G11: =VLOOKUP($D11,'[2]Khung_CTĐT_CNTT_K30 (2024)'!$B$10:$L$96,'Ke hoach giảng dạy CNTT'!G$6,0) -> 30 | H11: =VLOOKUP($D11,'[2]Khung_CTĐT_CNTT_K30 (2024)'!$B$10:$L$96,'Ke hoach giảng dạy CNTT'!H$6,0) -> 30 | I11: =VLOOKUP($D11,'[2]Khung_CTĐT_CNTT_K30 (2024)'!$B$10:$L$96,'Ke hoach giảng dạy CNTT'!I$6,0) -> 0 | J11: =VLOOKUP($D11,'[2]Khung_CTĐT_CNTT_K30 (2024)'!$B$10:$L$96,'Ke hoach giảng dạy CNTT'!J$6,0) -> 0 | K11: =VLOOKUP($D11,'[2]Khung_CTĐT_CNTT_K30 (2024)'!$B$10:$L$96,'Ke hoach giảng dạy CNTT'!K$6,0) -> BB | L11: =VLOOKUP($D11,'[2]Khung_CTĐT_CNTT_K30 (2024)'!$B$10:$L$96,'Ke hoach giảng dạy CNTT'!L$6,0) -> Không | M11: =VLOOKUP($D11,'[2]Khung_CTĐT_CNTT_K30 (2024)'!$B$10:$L$96,'Ke hoach giảng dạy CNTT'!M$6,0) -> Không | Q11: =Q10 -> 1 | R11: =IFERROR(VLOOKUP(D11,$D$9:D10,1,0),"")
B12: 1 | C12: 1 | D12: 71SSK110023 | E12: =VLOOKUP($D12,'[2]Khung_CTĐT_CNTT_K30 (2024)'!$B$10:$L$96,'Ke hoach giảng dạy CNTT'!E$6,0) -> Kỹ năng công dân toàn cầu | F12: =VLOOKUP($D12,'[2]Khung_CTĐT_CNTT_K30 (2024)'!$B$10:$L$96,'Ke hoach giảng dạy CNTT'!F$6,0) -> 3 | G12: =VLOOKUP($D12,'[2]Khung_CTĐT_CNTT_K30 (2024)'!$B$10:$L$96,'Ke hoach giảng dạy CNTT'!G$6,0) -> 45 | H12: =VLOOKUP($D12,'[2]Khung_CTĐT_CNTT_K30 (2024)'!$B$10:$L$96,'Ke hoach giảng dạy CNTT'!H$6,0) -> 0 | I12: =VLOOKUP($D12,'[2]Khung_CTĐT_CNTT_K30 (2024)'!$B$10:$L$96,'Ke hoach giảng dạy CNTT'!I$6,0) -> 0 | J12: =VLOOKUP($D12,'[2]Khung_CTĐT_CNTT_K30 (2024)'!$B$10:$L$96,'Ke hoach giảng dạy CNTT'!J$6,0) -> 0 | K12: =VLOOKUP($D12,'[2]Khung_CTĐT_CNTT_K30 (2024)'!$B$10:$L$96,'Ke hoach giảng dạy CNTT'!K$6,0) -> BB | L12: =VLOOKUP($D12,'[2]Khung_CTĐT_CNTT_K30 (2024)'!$B$10:$L$96,'Ke hoach giảng dạy CNTT'!L$6,0) -> Không | M12: =VLOOKUP($D12,'[2]Khung_CTĐT_CNTT_K30 (2024)'!$B$10:$L$96,'Ke hoach giảng dạy CNTT'!M$6,0) -> Không | Q12: =Q11 -> 1 | R12: =IFERROR(VLOOKUP(D12,$D$9:D11,1,0),"")
B13: 1 | C13: 1 | D13: 71NAD110013 | E13: =VLOOKUP($D13,'[2]Khung_CTĐT_CNTT_K30 (2024)'!$B$10:$L$96,'Ke hoach giảng dạy CNTT'!E$6,0) -> GDQP1: Đường lối QP và AN của ĐCSVN | F13: =VLOOKUP($D13,'[2]Khung_CTĐT_CNTT_K30 (2024)'!$B$10:$L$96,'Ke hoach giảng dạy CNTT'!F$6,0) -> 3 | G13: =VLOOKUP($D13,'[2]Khung_CTĐT_CNTT_K30 (2024)'!$B$10:$L$96,'Ke hoach giảng dạy CNTT'!G$6,0) -> 0 | H13: =VLOOKUP($D13,'[2]Khung_CTĐT_CNTT_K30 (2024)'!$B$10:$L$96,'Ke hoach giảng dạy CNTT'!H$6,0) -> 0 | I13: =VLOOKUP($D13,'[2]Khung_CTĐT_CNTT_K30 (2024)'!$B$10:$L$96,'Ke hoach giảng dạy CNTT'!I$6,0) -> 0 | J13: =VLOOKUP($D13,'[2]Khung_CTĐT_CNTT_K30 (2024)'!$B$10:$L$96,'Ke hoach giảng dạy CNTT'!J$6,0) -> 0 | K13: =VLOOKUP($D13,'[2]Khung_CTĐT_CNTT_K30 (2024)'!$B$10:$L$96,'Ke hoach giảng dạy CNTT'!K$6,0) -> BB | L13: =VLOOKUP($D13,'[2]Khung_CTĐT_CNTT_K30 (2024)'!$B$10:$L$96,'Ke hoach giảng dạy CNTT'!L$6,0) | M13: =VLOOKUP($D13,'[2]Khung_CTĐT_CNTT_K30 (2024)'!$B$10:$L$96,'Ke hoach giảng dạy CNTT'!M$6,0) | Q13: =Q12 -> 1 | R13: =IFERROR(VLOOKUP(D13,$D$9:D12,1,0),"")
B14: 1 | C14: 1 | D14: 71NAD210022 | E14: =VLOOKUP($D14,'[2]Khung_CTĐT_CNTT_K30 (2024)'!$B$10:$L$96,'Ke hoach giảng dạy CNTT'!E$6,0) -> GDQP2: Công tác quốc phòng và an ninh | F14: =VLOOKUP($D14,'[2]Khung_CTĐT_CNTT_K30 (2024)'!$B$10:$L$96,'Ke hoach giảng dạy CNTT'!F$6,0) -> 2 | G14: =VLOOKUP($D14,'[2]Khung_CTĐT_CNTT_K30 (2024)'!$B$10:$L$96,'Ke hoach giảng dạy CNTT'!G$6,0) -> 0 | H14: =VLOOKUP($D14,'[2]Khung_CTĐT_CNTT_K30 (2024)'!$B$10:$L$96,'Ke hoach giảng dạy CNTT'!H$6,0) -> 0 | I14: =VLOOKUP($D14,'[2]Khung_CTĐT_CNTT_K30 (2024)'!$B$10:$L$96,'Ke hoach giảng dạy CNTT'!I$6,0) -> 0 | J14: =VLOOKUP($D14,'[2]Khung_CTĐT_CNTT_K30 (2024)'!$B$10:$L$96,'Ke hoach giảng dạy CNTT'!J$6,0) -> 0 | K14: =VLOOKUP($D14,'[2]Khung_CTĐT_CNTT_K30 (2024)'!$B$10:$L$96,'Ke hoach giảng dạy CNTT'!K$6,0) -> BB | L14: =VLOOKUP($D14,'[2]Khung_CTĐT_CNTT_K30 (2024)'!$B$10:$L$96,'Ke hoach giảng dạy CNTT'!L$6,0) | M14: =VLOOKUP($D14,'[2]Khung_CTĐT_CNTT_K30 (2024)'!$B$10:$L$96,'Ke hoach giảng dạy CNTT'!M$6,0) | Q14: =Q13 -> 1 | R14: =IFERROR(VLOOKUP(D14,$D$9:D13,1,0),"")
B15: 1 | C15: 1 | D15: 71NAD310032 | E15: =VLOOKUP($D15,'[2]Khung_CTĐT_CNTT_K30 (2024)'!$B$10:$L$96,'Ke hoach giảng dạy CNTT'!E$6,0) -> GDQP3: Quân sự chung | F15: =VLOOKUP($D15,'[2]Khung_CTĐT_CNTT_K30 (2024)'!$B$10:$L$96,'Ke hoach giảng dạy CNTT'!F$6,0) -> 2 | G15: =VLOOKUP($D15,'[2]Khung_CTĐT_CNTT_K30 (2024)'!$B$10:$L$96,'Ke hoach giảng dạy CNTT'!G$6,0) -> 0 | H15: =VLOOKUP($D15,'[2]Khung_CTĐT_CNTT_K30 (2024)'!$B$10:$L$96,'Ke hoach giảng dạy CNTT'!H$6,0) -> 0 | I15: =VLOOKUP($D15,'[2]Khung_CTĐT_CNTT_K30 (2024)'!$B$10:$L$96,'Ke hoach giảng dạy CNTT'!I$6,0) -> 0 | J15: =VLOOKUP($D15,'[2]Khung_CTĐT_CNTT_K30 (2024)'!$B$10:$L$96,'Ke hoach giảng dạy CNTT'!J$6,0) -> 0 | K15: =VLOOKUP($D15,'[2]Khung_CTĐT_CNTT_K30 (2024)'!$B$10:$L$96,'Ke hoach giảng dạy CNTT'!K$6,0) -> BB | L15: =VLOOKUP($D15,'[2]Khung_CTĐT_CNTT_K30 (2024)'!$B$10:$L$96,'Ke hoach giảng dạy CNTT'!L$6,0) | M15: =VLOOKUP($D15,'[2]Khung_CTĐT_CNTT_K30 (2024)'!$B$10:$L$96,'Ke hoach giảng dạy CNTT'!M$6,0) | Q15: =Q14 -> 1 | R15: =IFERROR(VLOOKUP(D15,$D$9:D14,1,0),"")
B16: 1 | C16: 1 | D16: 71NAD410044 | E16: =VLOOKUP($D16,'[2]Khung_CTĐT_CNTT_K30 (2024)'!$B$10:$L$96,'Ke hoach giảng dạy CNTT'!E$6,0) -> GDQP4: Kỹ thuật chiến đấu bộ binh và chiến thuật | F16: =VLOOKUP($D16,'[2]Khung_CTĐT_CNTT_K30 (2024)'!$B$10:$L$96,'Ke hoach giảng dạy CNTT'!F$6,0) -> 4 | G16: =VLOOKUP($D16,'[2]Khung_CTĐT_CNTT_K30 (2024)'!$B$10:$L$96,'Ke hoach giảng dạy CNTT'!G$6,0) -> 0 | H16: =VLOOKUP($D16,'[2]Khung_CTĐT_CNTT_K30 (2024)'!$B$10:$L$96,'Ke hoach giảng dạy CNTT'!H$6,0) -> 0 | I16: =VLOOKUP($D16,'[2]Khung_CTĐT_CNTT_K30 (2024)'!$B$10:$L$96,'Ke hoach giảng dạy CNTT'!I$6,0) -> 0 | J16: =VLOOKUP($D16,'[2]Khung_CTĐT_CNTT_K30 (2024)'!$B$10:$L$96,'Ke hoach giảng dạy CNTT'!J$6,0) -> 0 | K16: =VLOOKUP($D16,'[2]Khung_CTĐT_CNTT_K30 (2024)'!$B$10:$L$96,'Ke hoach giảng dạy CNTT'!K$6,0) -> BB | L16: =VLOOKUP($D16,'[2]Khung_CTĐT_CNTT_K30 (2024)'!$B$10:$L$96,'Ke hoach giảng dạy CNTT'!L$6,0) | M16: =VLOOKUP($D16,'[2]Khung_CTĐT_CNTT_K30 (2024)'!$B$10:$L$96,'Ke hoach giảng dạy CNTT'!M$6,0) | Q16: =Q15 -> 1 | R16: =IFERROR(VLOOKUP(D16,$D$9:D15,1,0),"")
Q17: =Q16 -> 1 | R17: =IFERROR(VLOOKUP(D17,$D$9:D16,1,0),"")
A18: HK242 2 | B18: 2 | C18: 1 | D18: 71POLP10013 | E18: =VLOOKUP($D18,'[2]Khung_CTĐT_CNTT_K30 (2024)'!$B$10:$L$96,'Ke hoach giảng dạy CNTT'!E$6,0) -> Triết học Mác-Lênin | F18: =VLOOKUP($D18,'[2]Khung_CTĐT_CNTT_K30 (2024)'!$B$10:$L$96,'Ke hoach giảng dạy CNTT'!F$6,0) -> 3 | G18: =VLOOKUP($D18,'[2]Khung_CTĐT_CNTT_K30 (2024)'!$B$10:$L$96,'Ke hoach giảng dạy CNTT'!G$6,0) -> 45 | H18: =VLOOKUP($D18,'[2]Khung_CTĐT_CNTT_K30 (2024)'!$B$10:$L$96,'Ke hoach giảng dạy CNTT'!H$6,0) -> 0 | I18: =VLOOKUP($D18,'[2]Khung_CTĐT_CNTT_K30 (2024)'!$B$10:$L$96,'Ke hoach giảng dạy CNTT'!I$6,0) -> 0 | J18: =VLOOKUP($D18,'[2]Khung_CTĐT_CNTT_K30 (2024)'!$B$10:$L$96,'Ke hoach giảng dạy CNTT'!J$6,0) -> 0 | K18: =VLOOKUP($D18,'[2]Khung_CTĐT_CNTT_K30 (2024)'!$B$10:$L$96,'Ke hoach giảng dạy CNTT'!K$6,0) -> BB | L18: =VLOOKUP($D18,'[2]Khung_CTĐT_CNTT_K30 (2024)'!$B$10:$L$96,'Ke hoach giảng dạy CNTT'!L$6,0) -> Không | M18: =VLOOKUP($D18,'[2]Khung_CTĐT_CNTT_K30 (2024)'!$B$10:$L$96,'Ke hoach giảng dạy CNTT'!M$6,0) -> Không | N18: =SUM(F18:F22) -> 16 | P18: =P9+N18 -> 28 | Q18: 2 | R18: =IFERROR(VLOOKUP(D18,$D$9:D17,1,0),"")
B19: 2 | C19: 1 | D19: 71ENG210023 | E19: =VLOOKUP($D19,'[2]Khung_CTĐT_CNTT_K30 (2024)'!$B$10:$L$96,'Ke hoach giảng dạy CNTT'!E$6,0) -> Anh văn 2 (AV2) | F19: =VLOOKUP($D19,'[2]Khung_CTĐT_CNTT_K30 (2024)'!$B$10:$L$96,'Ke hoach giảng dạy CNTT'!F$6,0) -> 3 | G19: =VLOOKUP($D19,'[2]Khung_CTĐT_CNTT_K30 (2024)'!$B$10:$L$96,'Ke hoach giảng dạy CNTT'!G$6,0) -> 30 | H19: =VLOOKUP($D19,'[2]Khung_CTĐT_CNTT_K30 (2024)'!$B$10:$L$96,'Ke hoach giảng dạy CNTT'!H$6,0) -> 30 | I19: =VLOOKUP($D19,'[2]Khung_CTĐT_CNTT_K30 (2024)'!$B$10:$L$96,'Ke hoach giảng dạy CNTT'!I$6,0) -> 0 | J19: =VLOOKUP($D19,'[2]Khung_CTĐT_CNTT_K30 (2024)'!$B$10:$L$96,'Ke hoach giảng dạy CNTT'!J$6,0) -> 0 | K19: =VLOOKUP($D19,'[2]Khung_CTĐT_CNTT_K30 (2024)'!$B$10:$L$96,'Ke hoach giảng dạy CNTT'!K$6,0) -> BB | L19: =VLOOKUP($D19,'[2]Khung_CTĐT_CNTT_K30 (2024)'!$B$10:$L$96,'Ke hoach giảng dạy CNTT'!L$6,0) -> [71ENG110013]Anh văn 1 (AV1) | M19: =VLOOKUP($D19,'[2]Khung_CTĐT_CNTT_K30 (2024)'!$B$10:$L$96,'Ke hoach giảng dạy CNTT'!M$6,0) -> Không | Q19: =Q18 -> 2 | R19: =IFERROR(VLOOKUP(D19,$D$9:D18,1,0),"")
B20: 2 | C20: 1 | D20: 71ITMA10104 | E20: =VLOOKUP($D20,'[2]Khung_CTĐT_CNTT_K30 (2024)'!$B$10:$L$96,'Ke hoach giảng dạy CNTT'!E$6,0) -> Toán cao cấp và ứng dụng | F20: =VLOOKUP($D20,'[2]Khung_CTĐT_CNTT_K30 (2024)'!$B$10:$L$96,'Ke hoach giảng dạy CNTT'!F$6,0) -> 4 | G20: =VLOOKUP($D20,'[2]Khung_CTĐT_CNTT_K30 (2024)'!$B$10:$L$96,'Ke hoach giảng dạy CNTT'!G$6,0) -> 45 | H20: =VLOOKUP($D20,'[2]Khung_CTĐT_CNTT_K30 (2024)'!$B$10:$L$96,'Ke hoach giảng dạy CNTT'!H$6,0) -> 30 | I20: =VLOOKUP($D20,'[2]Khung_CTĐT_CNTT_K30 (2024)'!$B$10:$L$96,'Ke hoach giảng dạy CNTT'!I$6,0) -> 0 | J20: =VLOOKUP($D20,'[2]Khung_CTĐT_CNTT_K30 (2024)'!$B$10:$L$96,'Ke hoach giảng dạy CNTT'!J$6,0) -> 0 | K20: =VLOOKUP($D20,'[2]Khung_CTĐT_CNTT_K30 (2024)'!$B$10:$L$96,'Ke hoach giảng dạy CNTT'!K$6,0) -> BB | L20: =VLOOKUP($D20,'[2]Khung_CTĐT_CNTT_K30 (2024)'!$B$10:$L$96,'Ke hoach giảng dạy CNTT'!L$6,0) -> Không | M20: =VLOOKUP($D20,'[2]Khung_CTĐT_CNTT_K30 (2024)'!$B$10:$L$96,'Ke hoach giảng dạy CNTT'!M$6,0) -> Không | Q20: =Q19 -> 2 | R20: =IFERROR(VLOOKUP(D20,$D$9:D19,1,0),"")
B21: 2 | C21: 1 | D21: 71ITNW30103 | E21: =VLOOKUP($D21,'[2]Khung_CTĐT_CNTT_K30 (2024)'!$B$10:$L$96,'Ke hoach giảng dạy CNTT'!E$6,0) -> Nhập môn Mạng máy tính và điện toán đám mây | F21: =VLOOKUP($D21,'[2]Khung_CTĐT_CNTT_K30 (2024)'!$B$10:$L$96,'Ke hoach giảng dạy CNTT'!F$6,0) -> 3 | G21: =VLOOKUP($D21,'[2]Khung_CTĐT_CNTT_K30 (2024)'!$B$10:$L$96,'Ke hoach giảng dạy CNTT'!G$6,0) -> 30 | H21: =VLOOKUP($D21,'[2]Khung_CTĐT_CNTT_K30 (2024)'!$B$10:$L$96,'Ke hoach giảng dạy CNTT'!H$6,0) -> 30 | I21: =VLOOKUP($D21,'[2]Khung_CTĐT_CNTT_K30 (2024)'!$B$10:$L$96,'Ke hoach giảng dạy CNTT'!I$6,0) -> 0 | J21: =VLOOKUP($D21,'[2]Khung_CTĐT_CNTT_K30 (2024)'!$B$10:$L$96,'Ke hoach giảng dạy CNTT'!J$6,0) -> 0 | K21: =VLOOKUP($D21,'[2]Khung_CTĐT_CNTT_K30 (2024)'!$B$10:$L$96,'Ke hoach giảng dạy CNTT'!K$6,0) -> BB | L21: =VLOOKUP($D21,'[2]Khung_CTĐT_CNTT_K30 (2024)'!$B$10:$L$96,'Ke hoach giảng dạy CNTT'!L$6,0) -> Không | M21: =VLOOKUP($D21,'[2]Khung_CTĐT_CNTT_K30 (2024)'!$B$10:$L$96,'Ke hoach giảng dạy CNTT'!M$6,0) -> Không | Q21: =Q20 -> 2 | R21: =IFERROR(VLOOKUP(D21,$D$9:D20,1,0),"")
B22: 2 | C22: 1 | D22: 71ITSE30103 | E22: =VLOOKUP($D22,'[2]Khung_CTĐT_CNTT_K30 (2024)'!$B$10:$L$96,'Ke hoach giảng dạy CNTT'!E$6,0) -> Kỹ thuật lập trình | F22: =VLOOKUP($D22,'[2]Khung_CTĐT_CNTT_K30 (2024)'!$B$10:$L$96,'Ke hoach giảng dạy CNTT'!F$6,0) -> 3 | G22: =VLOOKUP($D22,'[2]Khung_CTĐT_CNTT_K30 (2024)'!$B$10:$L$96,'Ke hoach giảng dạy CNTT'!G$6,0) -> 30 | H22: =VLOOKUP($D22,'[2]Khung_CTĐT_CNTT_K30 (2024)'!$B$10:$L$96,'Ke hoach giảng dạy CNTT'!H$6,0) -> 30 | I22: =VLOOKUP($D22,'[2]Khung_CTĐT_CNTT_K30 (2024)'!$B$10:$L$96,'Ke hoach giảng dạy CNTT'!I$6,0) -> 0 | J22: =VLOOKUP($D22,'[2]Khung_CTĐT_CNTT_K30 (2024)'!$B$10:$L$96,'Ke hoach giảng dạy CNTT'!J$6,0) -> 0 | K22: =VLOOKUP($D22,'[2]Khung_CTĐT_CNTT_K30 (2024)'!$B$10:$L$96,'Ke hoach giảng dạy CNTT'!K$6,0) -> BB | L22: =VLOOKUP($D22,'[2]Khung_CTĐT_CNTT_K30 (2024)'!$B$10:$L$96,'Ke hoach giảng dạy CNTT'!L$6,0) -> Không | M22: =VLOOKUP($D22,'[2]Khung_CTĐT_CNTT_K30 (2024)'!$B$10:$L$96,'Ke hoach giảng dạy CNTT'!M$6,0) -> [71ITBS10203]Cơ sở lập trình | Q22: =Q21 -> 2 | R22: =IFERROR(VLOOKUP(D22,$D$9:D21,1,0),"")
Q23: =Q22 -> 2 | R23: =IFERROR(VLOOKUP(D23,$D$9:D22,1,0),"")
A24: HK243 3 | B24: 3 | C24: 1 | D24: 71POLE10022 | E24: =VLOOKUP($D24,'[2]Khung_CTĐT_CNTT_K30 (2024)'!$B$10:$L$96,'Ke hoach giảng dạy CNTT'!E$6,0) -> Kinh tế chính trị Mác-Lênin | F24: =VLOOKUP($D24,'[2]Khung_CTĐT_CNTT_K30 (2024)'!$B$10:$L$96,'Ke hoach giảng dạy CNTT'!F$6,0) -> 2 | G24: =VLOOKUP($D24,'[2]Khung_CTĐT_CNTT_K30 (2024)'!$B$10:$L$96,'Ke hoach giảng dạy CNTT'!G$6,0) -> 30 | H24: =VLOOKUP($D24,'[2]Khung_CTĐT_CNTT_K30 (2024)'!$B$10:$L$96,'Ke hoach giảng dạy CNTT'!H$6,0) -> 0 | I24: =VLOOKUP($D24,'[2]Khung_CTĐT_CNTT_K30 (2024)'!$B$10:$L$96,'Ke hoach giảng dạy CNTT'!I$6,0) -> 0 | J24: =VLOOKUP($D24,'[2]Khung_CTĐT_CNTT_K30 (2024)'!$B$10:$L$96,'Ke hoach giảng dạy CNTT'!J$6,0) -> 0 | K24: =VLOOKUP($D24,'[2]Khung_CTĐT_CNTT_K30 (2024)'!$B$10:$L$96,'Ke hoach giảng dạy CNTT'!K$6,0) -> BB | L24: =VLOOKUP($D24,'[2]Khung_CTĐT_CNTT_K30 (2024)'!$B$10:$L$96,'Ke hoach giảng dạy CNTT'!L$6,0) -> Không | M24: =VLOOKUP($D24,'[2]Khung_CTĐT_CNTT_K30 (2024)'!$B$10:$L$96,'Ke hoach giảng dạy CNTT'!M$6,0) -> [71POLP10013]Triết học Mác-Lênin | N24: =SUM(F24:F28) -> 14 | P24: =P18+N24 -> 42 | Q24: 3 | R24: =IFERROR(VLOOKUP(D24,$D$9:D23,1,0),"")
B25: 3 | C25: 1 | D25: 71ENG310033 | E25: =VLOOKUP($D25,'[2]Khung_CTĐT_CNTT_K30 (2024)'!$B$10:$L$96,'Ke hoach giảng dạy CNTT'!E$6,0) -> Anh văn 3 (AV3) | F25: =VLOOKUP($D25,'[2]Khung_CTĐT_CNTT_K30 (2024)'!$B$10:$L$96,'Ke hoach giảng dạy CNTT'!F$6,0) -> 3 | G25: =VLOOKUP($D25,'[2]Khung_CTĐT_CNTT_K30 (2024)'!$B$10:$L$96,'Ke hoach giảng dạy CNTT'!G$6,0) -> 30 | H25: =VLOOKUP($D25,'[2]Khung_CTĐT_CNTT_K30 (2024)'!$B$10:$L$96,'Ke hoach giảng dạy CNTT'!H$6,0) -> 30 | I25: =VLOOKUP($D25,'[2]Khung_CTĐT_CNTT_K30 (2024)'!$B$10:$L$96,'Ke hoach giảng dạy CNTT'!I$6,0) -> 0 | J25: =VLOOKUP($D25,'[2]Khung_CTĐT_CNTT_K30 (2024)'!$B$10:$L$96,'Ke hoach giảng dạy CNTT'!J$6,0) -> 0 | K25: =VLOOKUP($D25,'[2]Khung_CTĐT_CNTT_K30 (2024)'!$B$10:$L$96,'Ke hoach giảng dạy CNTT'!K$6,0) -> BB | L25: =VLOOKUP($D25,'[2]Khung_CTĐT_CNTT_K30 (2024)'!$B$10:$L$96,'Ke hoach giảng dạy CNTT'!L$6,0) -> [71ENG210023]Anh văn 2 (AV2) | M25: =VLOOKUP($D25,'[2]Khung_CTĐT_CNTT_K30 (2024)'!$B$10:$L$96,'Ke hoach giảng dạy CNTT'!M$6,0) -> Không | Q25: =Q24 -> 3 | R25: =IFERROR(VLOOKUP(D25,$D$9:D24,1,0),"")
B26: 3 | C26: 1 | D26: 71ITIS30103 | E26: =VLOOKUP($D26,'[2]Khung_CTĐT_CNTT_K30 (2024)'!$B$10:$L$96,'Ke hoach giảng dạy CNTT'!E$6,0) -> Cơ sở dữ liệu | F26: =VLOOKUP($D26,'[2]Khung_CTĐT_CNTT_K30 (2024)'!$B$10:$L$96,'Ke hoach giảng dạy CNTT'!F$6,0) -> 3 | G26: =VLOOKUP($D26,'[2]Khung_CTĐT_CNTT_K30 (2024)'!$B$10:$L$96,'Ke hoach giảng dạy CNTT'!G$6,0) -> 30 | H26: =VLOOKUP($D26,'[2]Khung_CTĐT_CNTT_K30 (2024)'!$B$10:$L$96,'Ke hoach giảng dạy CNTT'!H$6,0) -> 30 | I26: =VLOOKUP($D26,'[2]Khung_CTĐT_CNTT_K30 (2024)'!$B$10:$L$96,'Ke hoach giảng dạy CNTT'!I$6,0) -> 0 | J26: =VLOOKUP($D26,'[2]Khung_CTĐT_CNTT_K30 (2024)'!$B$10:$L$96,'Ke hoach giảng dạy CNTT'!J$6,0) -> 0 | K26: =VLOOKUP($D26,'[2]Khung_CTĐT_CNTT_K30 (2024)'!$B$10:$L$96,'Ke hoach giảng dạy CNTT'!K$6,0) -> BB | L26: =VLOOKUP($D26,'[2]Khung_CTĐT_CNTT_K30 (2024)'!$B$10:$L$96,'Ke hoach giảng dạy CNTT'!L$6,0) -> Không | M26: =VLOOKUP($D26,'[2]Khung_CTĐT_CNTT_K30 (2024)'!$B$10:$L$96,'Ke hoach giảng dạy CNTT'!M$6,0) -> Không | Q26: =Q25 -> 3 | R26: =IFERROR(VLOOKUP(D26,$D$9:D25,1,0),"")
B27: 3 | C27: 1 | D27: 71ITSE30303 | E27: =VLOOKUP($D27,'[2]Khung_CTĐT_CNTT_K30 (2024)'!$B$10:$L$96,'Ke hoach giảng dạy CNTT'!E$6,0) -> Cấu trúc dữ liệu và giải thuật | F27: =VLOOKUP($D27,'[2]Khung_CTĐT_CNTT_K30 (2024)'!$B$10:$L$96,'Ke hoach giảng dạy CNTT'!F$6,0) -> 3 | G27: =VLOOKUP($D27,'[2]Khung_CTĐT_CNTT_K30 (2024)'!$B$10:$L$96,'Ke hoach giảng dạy CNTT'!G$6,0) -> 30 | H27: =VLOOKUP($D27,'[2]Khung_CTĐT_CNTT_K30 (2024)'!$B$10:$L$96,'Ke hoach giảng dạy CNTT'!H$6,0) -> 30 | I27: =VLOOKUP($D27,'[2]Khung_CTĐT_CNTT_K30 (2024)'!$B$10:$L$96,'Ke hoach giảng dạy CNTT'!I$6,0) -> 0 | J27: =VLOOKUP($D27,'[2]Khung_CTĐT_CNTT_K30 (2024)'!$B$10:$L$96,'Ke hoach giảng dạy CNTT'!J$6,0) -> 0 | K27: =VLOOKUP($D27,'[2]Khung_CTĐT_CNTT_K30 (2024)'!$B$10:$L$96,'Ke hoach giảng dạy CNTT'!K$6,0) -> BB | L27: =VLOOKUP($D27,'[2]Khung_CTĐT_CNTT_K30 (2024)'!$B$10:$L$96,'Ke hoach giảng dạy CNTT'!L$6,0) -> Không | M27: =VLOOKUP($D27,'[2]Khung_CTĐT_CNTT_K30 (2024)'!$B$10:$L$96,'Ke hoach giảng dạy CNTT'!M$6,0) -> [71ITBS10203]Cơ sở lập trình | Q27: =Q26 -> 3 | R27: =IFERROR(VLOOKUP(D27,$D$9:D26,1,0),"")
B28: 3 | C28: 1 | D28: 71MATL10053 | E28: =VLOOKUP($D28,'[2]Khung_CTĐT_CNTT_K30 (2024)'!$B$10:$L$96,'Ke hoach giảng dạy CNTT'!E$6,0) -> Đại số tuyến tính và ứng dụng | F28: =VLOOKUP($D28,'[2]Khung_CTĐT_CNTT_K30 (2024)'!$B$10:$L$96,'Ke hoach giảng dạy CNTT'!F$6,0) -> 3 | G28: =VLOOKUP($D28,'[2]Khung_CTĐT_CNTT_K30 (2024)'!$B$10:$L$96,'Ke hoach giảng dạy CNTT'!G$6,0) -> 30 | H28: =VLOOKUP($D28,'[2]Khung_CTĐT_CNTT_K30 (2024)'!$B$10:$L$96,'Ke hoach giảng dạy CNTT'!H$6,0) -> 30 | I28: =VLOOKUP($D28,'[2]Khung_CTĐT_CNTT_K30 (2024)'!$B$10:$L$96,'Ke hoach giảng dạy CNTT'!I$6,0) -> 0 | J28: =VLOOKUP($D28,'[2]Khung_CTĐT_CNTT_K30 (2024)'!$B$10:$L$96,'Ke hoach giảng dạy CNTT'!J$6,0) -> 0 | K28: =VLOOKUP($D28,'[2]Khung_CTĐT_CNTT_K30 (2024)'!$B$10:$L$96,'Ke hoach giảng dạy CNTT'!K$6,0) -> BB | L28: =VLOOKUP($D28,'[2]Khung_CTĐT_CNTT_K30 (2024)'!$B$10:$L$96,'Ke hoach giảng dạy CNTT'!L$6,0) -> Không | M28: =VLOOKUP($D28,'[2]Khung_CTĐT_CNTT_K30 (2024)'!$B$10:$L$96,'Ke hoach giảng dạy CNTT'!M$6,0) -> Không | Q28: =Q27 -> 3 | R28: =IFERROR(VLOOKUP(D28,$D$9:D27,1,0),"")
Q29: =Q28 -> 3 | R29: =IFERROR(VLOOKUP(D29,$D$9:D28,1,0),"")
A30: HK251 4 | B30: 1 | C30: 2 | N30: =SUM(F30:F34) -> 13 | P30: =P24+N30 -> 55 | Q30: 4 | R30: =IFERROR(VLOOKUP(D30,$D$9:D29,1,0),"")
B31: 1 | C31: 2 | D31: 71ENG410043 | E31: =VLOOKUP($D31,'[2]Khung_CTĐT_CNTT_K30 (2024)'!$B$10:$L$96,'Ke hoach giảng dạy CNTT'!E$6,0) -> Anh văn 4 (AV4) | F31: =VLOOKUP($D31,'[2]Khung_CTĐT_CNTT_K30 (2024)'!$B$10:$L$96,'Ke hoach giảng dạy CNTT'!F$6,0) -> 3 | G31: =VLOOKUP($D31,'[2]Khung_CTĐT_CNTT_K30 (2024)'!$B$10:$L$96,'Ke hoach giảng dạy CNTT'!G$6,0) -> 30 | H31: =VLOOKUP($D31,'[2]Khung_CTĐT_CNTT_K30 (2024)'!$B$10:$L$96,'Ke hoach giảng dạy CNTT'!H$6,0) -> 30 | I31: =VLOOKUP($D31,'[2]Khung_CTĐT_CNTT_K30 (2024)'!$B$10:$L$96,'Ke hoach giảng dạy CNTT'!I$6,0) -> 0 | J31: =VLOOKUP($D31,'[2]Khung_CTĐT_CNTT_K30 (2024)'!$B$10:$L$96,'Ke hoach giảng dạy CNTT'!J$6,0) -> 0 | K31: =VLOOKUP($D31,'[2]Khung_CTĐT_CNTT_K30 (2024)'!$B$10:$L$96,'Ke hoach giảng dạy CNTT'!K$6,0) -> BB | L31: =VLOOKUP($D31,'[2]Khung_CTĐT_CNTT_K30 (2024)'!$B$10:$L$96,'Ke hoach giảng dạy CNTT'!L$6,0) -> [71ENG310033]Anh văn 3 (AV3) | M31: =VLOOKUP($D31,'[2]Khung_CTĐT_CNTT_K30 (2024)'!$B$10:$L$96,'Ke hoach giảng dạy CNTT'!M$6,0) -> Không | Q31: =Q30 -> 4 | R31: =IFERROR(VLOOKUP(D31,$D$9:D30,1,0),"")
B32: 1 | C32: 2 | D32: 71ITMA10403 | E32: =VLOOKUP($D32,'[2]Khung_CTĐT_CNTT_K30 (2024)'!$B$10:$L$96,'Ke hoach giảng dạy CNTT'!E$6,0) -> Toán rời rạc | F32: =VLOOKUP($D32,'[2]Khung_CTĐT_CNTT_K30 (2024)'!$B$10:$L$96,'Ke hoach giảng dạy CNTT'!F$6,0) -> 4 | G32: =VLOOKUP($D32,'[2]Khung_CTĐT_CNTT_K30 (2024)'!$B$10:$L$96,'Ke hoach giảng dạy CNTT'!G$6,0) -> 45 | H32: =VLOOKUP($D32,'[2]Khung_CTĐT_CNTT_K30 (2024)'!$B$10:$L$96,'Ke hoach giảng dạy CNTT'!H$6,0) -> 30 | I32: =VLOOKUP($D32,'[2]Khung_CTĐT_CNTT_K30 (2024)'!$B$10:$L$96,'Ke hoach giảng dạy CNTT'!I$6,0) -> 0 | J32: =VLOOKUP($D32,'[2]Khung_CTĐT_CNTT_K30 (2024)'!$B$10:$L$96,'Ke hoach giảng dạy CNTT'!J$6,0) -> 0 | K32: =VLOOKUP($D32,'[2]Khung_CTĐT_CNTT_K30 (2024)'!$B$10:$L$96,'Ke hoach giảng dạy CNTT'!K$6,0) -> BB | L32: =VLOOKUP($D32,'[2]Khung_CTĐT_CNTT_K30 (2024)'!$B$10:$L$96,'Ke hoach giảng dạy CNTT'!L$6,0) -> Không | M32: =VLOOKUP($D32,'[2]Khung_CTĐT_CNTT_K30 (2024)'!$B$10:$L$96,'Ke hoach giảng dạy CNTT'!M$6,0) -> [71ITMA10104]Toán cao cấp và ứng dụng | Q32: =Q31 -> 4 | R32: =IFERROR(VLOOKUP(D32,$D$9:D31,1,0),"")
B33: 1 | C33: 2 | D33: 71ITSE30203 | E33: =VLOOKUP($D33,'[2]Khung_CTĐT_CNTT_K30 (2024)'!$B$10:$L$96,'Ke hoach giảng dạy CNTT'!E$6,0) -> Lập trình hướng đối tượng | F33: =VLOOKUP($D33,'[2]Khung_CTĐT_CNTT_K30 (2024)'!$B$10:$L$96,'Ke hoach giảng dạy CNTT'!F$6,0) -> 3 | G33: =VLOOKUP($D33,'[2]Khung_CTĐT_CNTT_K30 (2024)'!$B$10:$L$96,'Ke hoach giảng dạy CNTT'!G$6,0) -> 30 | H33: =VLOOKUP($D33,'[2]Khung_CTĐT_CNTT_K30 (2024)'!$B$10:$L$96,'Ke hoach giảng dạy CNTT'!H$6,0) -> 30 | I33: =VLOOKUP($D33,'[2]Khung_CTĐT_CNTT_K30 (2024)'!$B$10:$L$96,'Ke hoach giảng dạy CNTT'!I$6,0) -> 0 | J33: =VLOOKUP($D33,'[2]Khung_CTĐT_CNTT_K30 (2024)'!$B$10:$L$96,'Ke hoach giảng dạy CNTT'!J$6,0) -> 0 | K33: =VLOOKUP($D33,'[2]Khung_CTĐT_CNTT_K30 (2024)'!$B$10:$L$96,'Ke hoach giảng dạy CNTT'!K$6,0) -> BB | L33: =VLOOKUP($D33,'[2]Khung_CTĐT_CNTT_K30 (2024)'!$B$10:$L$96,'Ke hoach giảng dạy CNTT'!L$6,0) -> Không | M33: =VLOOKUP($D33,'[2]Khung_CTĐT_CNTT_K30 (2024)'!$B$10:$L$96,'Ke hoach giảng dạy CNTT'!M$6,0) -> [71ITBS10203]Cơ sở lập trình | Q33: =Q32 -> 4 | R33: =IFERROR(VLOOKUP(D33,$D$9:D32,1,0),"")
B34: 1 | C34: 2 | D34: 71ITSE30503 | E34: =VLOOKUP($D34,'[2]Khung_CTĐT_CNTT_K30 (2024)'!$B$10:$L$96,'Ke hoach giảng dạy CNTT'!E$6,0) -> Lập trình ứng dụng Web | F34: =VLOOKUP($D34,'[2]Khung_CTĐT_CNTT_K30 (2024)'!$B$10:$L$96,'Ke hoach giảng dạy CNTT'!F$6,0) -> 3 | G34: =VLOOKUP($D34,'[2]Khung_CTĐT_CNTT_K30 (2024)'!$B$10:$L$96,'Ke hoach giảng dạy CNTT'!G$6,0) -> 30 | H34: =VLOOKUP($D34,'[2]Khung_CTĐT_CNTT_K30 (2024)'!$B$10:$L$96,'Ke hoach giảng dạy CNTT'!H$6,0) -> 30 | I34: =VLOOKUP($D34,'[2]Khung_CTĐT_CNTT_K30 (2024)'!$B$10:$L$96,'Ke hoach giảng dạy CNTT'!I$6,0) -> 0 | J34: =VLOOKUP($D34,'[2]Khung_CTĐT_CNTT_K30 (2024)'!$B$10:$L$96,'Ke hoach giảng dạy CNTT'!J$6,0) -> 0 | K34: =VLOOKUP($D34,'[2]Khung_CTĐT_CNTT_K30 (2024)'!$B$10:$L$96,'Ke hoach giảng dạy CNTT'!K$6,0) -> BB | L34: =VLOOKUP($D34,'[2]Khung_CTĐT_CNTT_K30 (2024)'!$B$10:$L$96,'Ke hoach giảng dạy CNTT'!L$6,0) -> Không | M34: =VLOOKUP($D34,'[2]Khung_CTĐT_CNTT_K30 (2024)'!$B$10:$L$96,'Ke hoach giảng dạy CNTT'!M$6,0) -> [71ITBS10203]Cơ sở lập trình | Q34: =Q33 -> 4 | R34: =IFERROR(VLOOKUP(D34,$D$9:D33,1,0),"")
A35: HK252 5 | B35: 2 | D35: 71POLS10032 | E35: =VLOOKUP($D35,'[2]Khung_CTĐT_CNTT_K30 (2024)'!$B$10:$L$96,'Ke hoach giảng dạy CNTT'!E$6,0) -> Chủ nghĩa xã hội khoa học | F35: =VLOOKUP($D35,'[2]Khung_CTĐT_CNTT_K30 (2024)'!$B$10:$L$96,'Ke hoach giảng dạy CNTT'!F$6,0) -> 2 | G35: =VLOOKUP($D35,'[2]Khung_CTĐT_CNTT_K30 (2024)'!$B$10:$L$96,'Ke hoach giảng dạy CNTT'!G$6,0) -> 30 | H35: =VLOOKUP($D35,'[2]Khung_CTĐT_CNTT_K30 (2024)'!$B$10:$L$96,'Ke hoach giảng dạy CNTT'!H$6,0) -> 0 | I35: =VLOOKUP($D35,'[2]Khung_CTĐT_CNTT_K30 (2024)'!$B$10:$L$96,'Ke hoach giảng dạy CNTT'!I$6,0) -> 0 | J35: =VLOOKUP($D35,'[2]Khung_CTĐT_CNTT_K30 (2024)'!$B$10:$L$96,'Ke hoach giảng dạy CNTT'!J$6,0) -> 0 | K35: =VLOOKUP($D35,'[2]Khung_CTĐT_CNTT_K30 (2024)'!$B$10:$L$96,'Ke hoach giảng dạy CNTT'!K$6,0) -> BB | L35: =VLOOKUP($D35,'[2]Khung_CTĐT_CNTT_K30 (2024)'!$B$10:$L$96,'Ke hoach giảng dạy CNTT'!L$6,0) -> Không | M35: =VLOOKUP($D35,'[2]Khung_CTĐT_CNTT_K30 (2024)'!$B$10:$L$96,'Ke hoach giảng dạy CNTT'!M$6,0) -> [71POLP10013]Triết học Mác-Lênin | N35: =SUM(F35:F37)+6 -> 14 | P35: =P30+N35 -> 69 | Q35: 5 | R35: =IFERROR(VLOOKUP(D35,$D$9:D34,1,0),"")
B36: 2 | C36: 2 | D36: 71ENG510053 | E36: =VLOOKUP($D36,'[2]Khung_CTĐT_CNTT_K30 (2024)'!$B$10:$L$96,'Ke hoach giảng dạy CNTT'!E$6,0) -> Anh văn 5 (AV5) | F36: =VLOOKUP($D36,'[2]Khung_CTĐT_CNTT_K30 (2024)'!$B$10:$L$96,'Ke hoach giảng dạy CNTT'!F$6,0) -> 3 | G36: =VLOOKUP($D36,'[2]Khung_CTĐT_CNTT_K30 (2024)'!$B$10:$L$96,'Ke hoach giảng dạy CNTT'!G$6,0) -> 30 | H36: =VLOOKUP($D36,'[2]Khung_CTĐT_CNTT_K30 (2024)'!$B$10:$L$96,'Ke hoach giảng dạy CNTT'!H$6,0) -> 30 | I36: =VLOOKUP($D36,'[2]Khung_CTĐT_CNTT_K30 (2024)'!$B$10:$L$96,'Ke hoach giảng dạy CNTT'!I$6,0) -> 0 | J36: =VLOOKUP($D36,'[2]Khung_CTĐT_CNTT_K30 (2024)'!$B$10:$L$96,'Ke hoach giảng dạy CNTT'!J$6,0) -> 0 | K36: =VLOOKUP($D36,'[2]Khung_CTĐT_CNTT_K30 (2024)'!$B$10:$L$96,'Ke hoach giảng dạy CNTT'!K$6,0) -> BB | L36: =VLOOKUP($D36,'[2]Khung_CTĐT_CNTT_K30 (2024)'!$B$10:$L$96,'Ke hoach giảng dạy CNTT'!L$6,0) -> [71ENG410043]Anh văn 4 (AV4) | M36: =VLOOKUP($D36,'[2]Khung_CTĐT_CNTT_K30 (2024)'!$B$10:$L$96,'Ke hoach giảng dạy CNTT'!M$6,0) -> Không | Q36: =Q35 -> 5 | R36: =IFERROR(VLOOKUP(D36,$D$9:D35,1,0),"")
B37: 2 | C37: 2 | D37: 71ITDS30103 | E37: =VLOOKUP($D37,'[2]Khung_CTĐT_CNTT_K30 (2024)'!$B$10:$L$96,'Ke hoach giảng dạy CNTT'!E$6,0) -> Các nền tảng phát triển phần mềm | F37: =VLOOKUP($D37,'[2]Khung_CTĐT_CNTT_K30 (2024)'!$B$10:$L$96,'Ke hoach giảng dạy CNTT'!F$6,0) -> 3 | G37: =VLOOKUP($D37,'[2]Khung_CTĐT_CNTT_K30 (2024)'!$B$10:$L$96,'Ke hoach giảng dạy CNTT'!G$6,0) -> 30 | H37: =VLOOKUP($D37,'[2]Khung_CTĐT_CNTT_K30 (2024)'!$B$10:$L$96,'Ke hoach giảng dạy CNTT'!H$6,0) -> 30 | I37: =VLOOKUP($D37,'[2]Khung_CTĐT_CNTT_K30 (2024)'!$B$10:$L$96,'Ke hoach giảng dạy CNTT'!I$6,0) -> 0 | J37: =VLOOKUP($D37,'[2]Khung_CTĐT_CNTT_K30 (2024)'!$B$10:$L$96,'Ke hoach giảng dạy CNTT'!J$6,0) -> 0 | K37: =VLOOKUP($D37,'[2]Khung_CTĐT_CNTT_K30 (2024)'!$B$10:$L$96,'Ke hoach giảng dạy CNTT'!K$6,0) -> BB | L37: =VLOOKUP($D37,'[2]Khung_CTĐT_CNTT_K30 (2024)'!$B$10:$L$96,'Ke hoach giảng dạy CNTT'!L$6,0) -> Không | M37: =VLOOKUP($D37,'[2]Khung_CTĐT_CNTT_K30 (2024)'!$B$10:$L$96,'Ke hoach giảng dạy CNTT'!M$6,0) -> [71ITBS10103]Nhập môn công nghệ thông tin | Q37: =Q36 -> 5 | R37: =IFERROR(VLOOKUP(D37,$D$9:D36,1,0),"")
C38: Chọn 2 trong 6 HP tự chọn Cơ sở ngành | Q38: =Q37 -> 5 | R38: =IFERROR(VLOOKUP(D38,$D$9:D37,1,0),"")
B39: 2 | C39: 2 | D39: 71ISBC30103 | E39: =VLOOKUP($D39,'[2]Khung_CTĐT_CNTT_K30 (2024)'!$B$10:$L$96,'Ke hoach giảng dạy CNTT'!E$6,0) -> Nhập môn Hệ thống thông tin | F39: =VLOOKUP($D39,'[2]Khung_CTĐT_CNTT_K30 (2024)'!$B$10:$L$96,'Ke hoach giảng dạy CNTT'!F$6,0) -> 3 | G39: =VLOOKUP($D39,'[2]Khung_CTĐT_CNTT_K30 (2024)'!$B$10:$L$96,'Ke hoach giảng dạy CNTT'!G$6,0) -> 30 | H39: =VLOOKUP($D39,'[2]Khung_CTĐT_CNTT_K30 (2024)'!$B$10:$L$96,'Ke hoach giảng dạy CNTT'!H$6,0) -> 30 | I39: =VLOOKUP($D39,'[2]Khung_CTĐT_CNTT_K30 (2024)'!$B$10:$L$96,'Ke hoach giảng dạy CNTT'!I$6,0) -> 0 | J39: =VLOOKUP($D39,'[2]Khung_CTĐT_CNTT_K30 (2024)'!$B$10:$L$96,'Ke hoach giảng dạy CNTT'!J$6,0) -> 0 | K39: =VLOOKUP($D39,'[2]Khung_CTĐT_CNTT_K30 (2024)'!$B$10:$L$96,'Ke hoach giảng dạy CNTT'!K$6,0) -> TC209 | L39: =VLOOKUP($D39,'[2]Khung_CTĐT_CNTT_K30 (2024)'!$B$10:$L$96,'Ke hoach giảng dạy CNTT'!L$6,0) -> Không | M39: =VLOOKUP($D39,'[2]Khung_CTĐT_CNTT_K30 (2024)'!$B$10:$L$96,'Ke hoach giảng dạy CNTT'!M$6,0) -> [71ITBS10103]Nhập môn công nghệ thông tin | Q39: =Q38 -> 5 | R39: =IFERROR(VLOOKUP(D39,$D$9:D38,1,0),"")
B40: 2 | C40: 2 | D40: 71ITNW30303 | E40: =VLOOKUP($D40,'[2]Khung_CTĐT_CNTT_K30 (2024)'!$B$10:$L$96,'Ke hoach giảng dạy CNTT'!E$6,0) -> An ninh Mạng máy tính | F40: =VLOOKUP($D40,'[2]Khung_CTĐT_CNTT_K30 (2024)'!$B$10:$L$96,'Ke hoach giảng dạy CNTT'!F$6,0) -> 3 | G40: =VLOOKUP($D40,'[2]Khung_CTĐT_CNTT_K30 (2024)'!$B$10:$L$96,'Ke hoach giảng dạy CNTT'!G$6,0) -> 30 | H40: =VLOOKUP($D40,'[2]Khung_CTĐT_CNTT_K30 (2024)'!$B$10:$L$96,'Ke hoach giảng dạy CNTT'!H$6,0) -> 30 | I40: =VLOOKUP($D40,'[2]Khung_CTĐT_CNTT_K30 (2024)'!$B$10:$L$96,'Ke hoach giảng dạy CNTT'!I$6,0) -> 0 | J40: =VLOOKUP($D40,'[2]Khung_CTĐT_CNTT_K30 (2024)'!$B$10:$L$96,'Ke hoach giảng dạy CNTT'!J$6,0) -> 0 | K40: =VLOOKUP($D40,'[2]Khung_CTĐT_CNTT_K30 (2024)'!$B$10:$L$96,'Ke hoach giảng dạy CNTT'!K$6,0) -> TC209 | L40: =VLOOKUP($D40,'[2]Khung_CTĐT_CNTT_K30 (2024)'!$B$10:$L$96,'Ke hoach giảng dạy CNTT'!L$6,0) -> Không | M40: =VLOOKUP($D40,'[2]Khung_CTĐT_CNTT_K30 (2024)'!$B$10:$L$96,'Ke hoach giảng dạy CNTT'!M$6,0) -> Không | Q40: =Q39 -> 5 | R40: =IFERROR(VLOOKUP(D40,$D$9:D39,1,0),"")
B41: 2 | C41: 2 | D41: 71ITDS40203 | E41: =VLOOKUP($D41,'[2]Khung_CTĐT_CNTT_K30 (2024)'!$B$10:$L$96,'Ke hoach giảng dạy CNTT'!E$6,0) -> Xác xuất thống kê ứng dụng | F41: =VLOOKUP($D41,'[2]Khung_CTĐT_CNTT_K30 (2024)'!$B$10:$L$96,'Ke hoach giảng dạy CNTT'!F$6,0) -> 3 | G41: =VLOOKUP($D41,'[2]Khung_CTĐT_CNTT_K30 (2024)'!$B$10:$L$96,'Ke hoach giảng dạy CNTT'!G$6,0) -> 30 | H41: =VLOOKUP($D41,'[2]Khung_CTĐT_CNTT_K30 (2024)'!$B$10:$L$96,'Ke hoach giảng dạy CNTT'!H$6,0) -> 30 | I41: =VLOOKUP($D41,'[2]Khung_CTĐT_CNTT_K30 (2024)'!$B$10:$L$96,'Ke hoach giảng dạy CNTT'!I$6,0) -> 0 | J41: =VLOOKUP($D41,'[2]Khung_CTĐT_CNTT_K30 (2024)'!$B$10:$L$96,'Ke hoach giảng dạy CNTT'!J$6,0) -> 0 | K41: =VLOOKUP($D41,'[2]Khung_CTĐT_CNTT_K30 (2024)'!$B$10:$L$96,'Ke hoach giảng dạy CNTT'!K$6,0) -> TC209 | L41: =VLOOKUP($D41,'[2]Khung_CTĐT_CNTT_K30 (2024)'!$B$10:$L$96,'Ke hoach giảng dạy CNTT'!L$6,0) -> Không | M41: =VLOOKUP($D41,'[2]Khung_CTĐT_CNTT_K30 (2024)'!$B$10:$L$96,'Ke hoach giảng dạy CNTT'!M$6,0) -> [71ITMA10403]Toán rời rạc | Q41: =Q40 -> 5 | R41: =IFERROR(VLOOKUP(D41,$D$9:D40,1,0),"")
B42: 2 | C42: 2 | D42: 71ITIS30303 | E42: =VLOOKUP($D42,'[2]Khung_CTĐT_CNTT_K30 (2024)'!$B$10:$L$96,'Ke hoach giảng dạy CNTT'!E$6,0) -> Quản lý Dự án Công nghệ Thông tin | F42: =VLOOKUP($D42,'[2]Khung_CTĐT_CNTT_K30 (2024)'!$B$10:$L$96,'Ke hoach giảng dạy CNTT'!F$6,0) -> 3 | G42: =VLOOKUP($D42,'[2]Khung_CTĐT_CNTT_K30 (2024)'!$B$10:$L$96,'Ke hoach giảng dạy CNTT'!G$6,0) -> 30 | H42: =VLOOKUP($D42,'[2]Khung_CTĐT_CNTT_K30 (2024)'!$B$10:$L$96,'Ke hoach giảng dạy CNTT'!H$6,0) -> 30 | I42: =VLOOKUP($D42,'[2]Khung_CTĐT_CNTT_K30 (2024)'!$B$10:$L$96,'Ke hoach giảng dạy CNTT'!I$6,0) -> 0 | J42: =VLOOKUP($D42,'[2]Khung_CTĐT_CNTT_K30 (2024)'!$B$10:$L$96,'Ke hoach giảng dạy CNTT'!J$6,0) -> 0 | K42: =VLOOKUP($D42,'[2]Khung_CTĐT_CNTT_K30 (2024)'!$B$10:$L$96,'Ke hoach giảng dạy CNTT'!K$6,0) -> TC209 | L42: =VLOOKUP($D42,'[2]Khung_CTĐT_CNTT_K30 (2024)'!$B$10:$L$96,'Ke hoach giảng dạy CNTT'!L$6,0) -> Không | M42: =VLOOKUP($D42,'[2]Khung_CTĐT_CNTT_K30 (2024)'!$B$10:$L$96,'Ke hoach giảng dạy CNTT'!M$6,0) -> [71ITBS10103]Nhập môn công nghệ thông tin | Q42: =Q40 -> 5 | R42: =IFERROR(VLOOKUP(D42,$D$9:D40,1,0),"")
...

Sheet MaBoMon
A1: TRƯỜNG ĐẠI HỌC VĂN LANG PHÒNG ĐÀO TẠO
A2: DANH MỤC BỘ MÔN THEO TỜ TRÌNH ĐÃ ĐƯỢC HIỆU TRƯỞNG PHÊ DUYỆT (Theo tờ trình số 01/TTr-ĐHVL-BCL, ngày 27 tháng 02 năm 2021)
A4: STT | B4: Mã Bộ môn | C4: Tên Bộ môn | D4: Mã đơn vị | E4: Tên đơn vị | F4: Ghi chú
A5: 1 | B5: 200110101 | C5: Bộ môn Kế toán quản trị | D5: 2001101 | E5: Khoa Kế toán - Kiểm toán
A6: 2 | B6: 200110102 | C6: Bộ môn Kế toán tài chính và Thực hành kế toán | D6: 2001101 | E6: Khoa Kế toán - Kiểm toán
A7: 3 | B7: 200110103 | C7: Bộ môn Nguyên lý kế toán và Kiểm toán | D7: 2001101 | E7: Khoa Kế toán - Kiểm toán
A8: 4 | B8: 200110201 | C8: Bộ môn Luật Hiến pháp - Hành chính | D8: 2001102 | E8: Khoa Luật
A9: 5 | B9: 200110202 | C9: Bộ môn Luật Quốc tế | D9: 2001102 | E9: Khoa Luật
A10: 6 | B10: 200110203 | C10: Bộ môn Luật Thương mại - Dân sự | D10: 2001102 | E10: Khoa Luật
A11: 7 | B11: 200110204 | C11: Bộ môn Luật hình sự | D11: 2001102 | E11: Khoa Luật
A12: 8 | B12: 200110301 | C12: Bộ môn Kỹ năng ngôn ngữ | D12: 2001103 | E12: Khoa Ngoại ngữ
A13: 9 | B13: 200110302 | C13: Bộ môn Ngoại ngữ 2 Và Ngôn Ngữ Trung | D13: 2001103 | E13: Khoa Ngoại ngữ
A14: 10 | B14: 200110303 | C14: Bộ môn Ngôn ngữ chuyên ngành | D14: 2001103 | E14: Khoa Ngoại ngữ
A15: 11 | B15: 200110304 | C15: Bộ môn Chương trình đào tạo đặc biệt & liên kết quốc tế | D15: 2001103 | E15: Khoa Ngoại ngữ
A16: 12 | B16: 200110401 | C16: Bộ môn Quản Trị Chất Lượng | D16: 2001104 | E16: Khoa Quản trị kinh doanh
... A97: 93 | B97: 200113301 | C97: Bộ môn Giáo dục quốc phòng và an ninh | D97: 2001133 | E97: Phòng Giáo dục Quốc phòng và An ninh
A98: 94 | B98: 200113501 | C98: Bộ môn Giáo dục thể chất | D98: 2001135 | E98: Trung tâm thể dục thể thao
E101: Cập nhật ngày 02 tháng 7 năm 2021 (Theo dữ liệu HRM cung cấp)
